Workbook

Sheet Consolidado_OUC-FL
F2: OPERAÇÃO URBANA CONSORCIADA FARIA LIMA
F3: Lei 13.769/04, alterada pelas leis 13.871/04, 15.519/11, 16.242/15 e 18.175/24
F4: POSIÇÃO EM 08/04/2026
F6: QUADRO GERAL DE DISTRIBUIÇÃO DE ESTOQUES DE ACA EM M² - LEI 13.769/2004
F7: SETORES | G7: ESTOQUE MÁXIMO (m²) PREVISTO PARA OS SETORES | I7: ESTOQUE MÁXIMO PREVISTO PARA OUCFL - LEI 13.769/04 ( R+ nR) | J7: ESTOQUE CONSUMIDO (m²) - LEI 13.769/04 | L7: SALDO DE ESTOQUE MÁXIMO PREVISTO PARA OS SETORES (Remanescente lei 13.769/04) | N7: ESTOQUE (m²) À RESTITUIR APÓS DESVINCULAÇÃO OU MODIFICAÇÃO DE USO (90 dias) | P7: SALDO DE ESTOQUE GERAL DISPONÍVEL PARA A OPERAÇÃO URBANA
G8: R | H8: NR | J8: R | K8: NR | L8: R | M8: NR | N8: R | O8: NR | P8: R | Q8: NR
F9: HELIO PELEGRINO | G9: 292445 | H9: 182505 | I9: =G9+H9 -> 474950 | J9: =279084.28 -> 279084.28 | K9: =162600.47 -> 162600.47 | L9: =(G9-J9)+N9 -> 13360.72 | M9: =(H9-K9)+O9 -> 19904.53 | N9: 0 | O9: 0 | P9: =N14 -> 22996.43 | X9: 13360.72 | Y9: 19904.53
F10: FARIA LIMA | G10: 288190 | H10: 73715 | I10: =G10+H10 -> 361905 | J10: =133370.09 -> 133370.09 | K10: =73552.78 -> 73552.78 | L10: =(G10-J10)+N10 -> 161822.14 | M10: =(H10-K10)+O10 -> 162.22 | N10: =GETPIVOTDATA("Soma de ACA-R",'5_18175'!$A$30,"SETOR OUC","FARIA LIMA") -> 7002.23 | O10: 0 | X10: 168824.37 | Y10: 162.22
F11: PINHEIROS | G11: 286695 | H11: 96600 | I11: =G11+H11 -> 383295 | J11: =146445.55 -> 146445.55 | K11: =95217.97 -> 95217.97 | L11: =(G11-J11)+N11 -> 140249.45 | M11: =(H11-K11)+O11 -> 1382.03 | N11: 0 | O11: 0 | X11: 140249.45 | Y11: 1382.03
F12: OLIMPÍADAS | G12: 190440 | H12: 95565 | I12: =G12+H12 -> 286005 | J12: =87199.88 -> 87199.88 | K12: 95563.02 | L12: =(G12-J12)+N12 -> 119234.32 | M12: =(H12-K12)+O12 -> 1.98 | N12: =GETPIVOTDATA("Soma de ACA-R",'5_18175'!$A$30,"SETOR OUC","OLIMPÍADAS") -> 15994.2 | O12: 0 | X12: 103240.12 | Y12: 1.98
F13: Total | G13: =SUM(G9:G12) -> 1057770 | H13: =SUM(H9:H12) -> 448385 | I13: =SUM(I9:I12) -> 1506155 | J13: =SUM(J9:J12) -> 646099.8 | K13: =SUM(K9:K12) -> 426934.24 | L13: =SUM(L9:L12) -> 434666.63 | M13: =SUM(M9:M12) -> 21450.76 | N13: =SUM(N9:N12) -> 22996.43 | O13: =SUM(O9:O12) -> 0
G14: =G13+H13 -> 1506155 | J14: =J13+K13 -> 1073034 | L14: =L13+M13 -> 456117.39 | N14: =N13+O13 -> 22996.43
F16: QUADRO GERAL DE DISTRIBUIÇÃO DE ESTOQUES DE ACA EM M² - (A PARTIR DA LEI 18.175/24)
F17: SETORES | G17: ESTOQUE MÁXIMO (por uso e por setor(m²) PREVISTO PARA OS SETORES ( LEI 13.769/04) | I17: ESTOQUE MÁXIMO PREVISTO POR SETOR PARA OUCFL - Lei 18.175/24 | J17: ESTOQUE CONSUMIDO (m²) - (Lei 13.769/04) | L17: ESTOQUE EM CONSUMIDO (m²) - (a partir da Lei 18.175/24) | N17: ESTOQUE EM ANALISE (m²) - (a partir da Lei 18.175/24) | P17: ESTOQUE MAXIMO (m²) PREVISTO PARA OS SETORES PELA LEI 18.175/24 | R17: SALDO DE ESTOQUE GERAL DISPONIVEL PARA A OPERAÇÃO URBANA - lei 18.175/24
G18: R | H18: NR | J18: R | K18: NR | L18: R | M18: NR | N18: R | O18: NR | P18: R | Q18: NR | R18: R | S18: NR
F19: HELIO PELEGRINO | G19: 292445 | H19: 182505 | I19: 576700 | J19: =J9 -> 279084.28 | K19: =K9 -> 162600.47 | L19: ='5_18175'!R7 -> 21066.57 | M19: ='5_18175'!S7 -> 12448.27 | N19: =GETPIVOTDATA("Soma de ACA-R",'5_18175'!$A$6,"SETOR OUC","HÉLIO PELEGRINO") -> 4854.71 | O19: =GETPIVOTDATA("Soma de ACA-NR",'5_18175'!$A$6,"SETOR OUC","HÉLIO PELEGRINO") -> 175.83 | P19: =101750-L19-M19 -> 68235.16 | R19: =250000-L24 -> 128601.6
F20: FARIA LIMA | G20: 288190 | H20: 73715 | I20: 402905 | J20: =J10 -> 133370.09 | K20: =K10 -> 73552.78 | L20: ='5_18175'!R8 -> 19231.15 | M20: ='5_18175'!S8 -> 7722.52 | N20: =GETPIVOTDATA("Soma de ACA-R",'5_18175'!$A$6,"SETOR OUC","FARIA LIMA") -> 0 | O20: =GETPIVOTDATA("Soma de ACA-NR",'5_18175'!$A$6,"SETOR OUC","FARIA LIMA") -> 0 | P20: =41000-L20-M20 -> 14046.33
F21: PINHEIROS | G21: 286695 | H21: 96600 | I21: 437145 | J21: =J11 -> 146445.55 | K21: =K11 -> 95217.97 | L21: ='5_18175'!R9 -> 21914.1 | M21: ='5_18175'!S9 -> 0 | N21: =GETPIVOTDATA("Soma de ACA-R",'5_18175'!$A$6,"SETOR OUC","PINHEIROS") -> 0 | O21: =GETPIVOTDATA("Soma de ACA-NR",'5_18175'!$A$6,"SETOR OUC","PINHEIROS") -> 0 | P21: =53850-L21-M21 -> 31935.9
F22: OLIMPÍADAS | G22: 190440 | H22: 95565 | I22: 339405 | J22: =J12 -> 87199.88 | K22: =K12 -> 95563.02 | L22: ='5_18175'!R10 -> 8140.2 | M22: ='5_18175'!S10 -> 30875.59 | N22: =GETPIVOTDATA("Soma de ACA-R",'5_18175'!$A$6,"SETOR OUC","OLIMPÍADAS") -> 0 | O22: =GETPIVOTDATA("Soma de ACA-NR",'5_18175'!$A$6,"SETOR OUC","OLIMPÍADAS") -> 0 | P22: =53400-L22-M22 -> 14384.21
F23: Total | G23: =SUM(G19:G22) -> 1057770 | H23: =SUM(H19:H22) -> 448385 | I23: =SUM(I19:I22) -> 1756155 | J23: =SUM(J19:J22) -> 646099.8 | K23: =SUM(K19:K22) -> 426934.24 | L23: =SUM(L19:L22) -> 70352.02 | M23: =SUM(M19:M22) -> 51046.38 | N23: =SUM(N19:N22) -> 4854.71 | O23: =SUM(O19:O22) -> 175.83 | P23: =SUM(P19:Q22) -> 128601.6 | U23: =R19-N24 -> 123571.06
G24: =G23+H23 -> 1506155 | J24: =J23+K23 -> 1073034 | L24: =L23+M23 -> 121398.4 | N24: =N23+O23 -> 5030.54
F26: LIMITE DE ESTOQUE (m²) PARA EFEITO DE OFERTA DE CEPAC | I26: RESUMO DE CEPAC | L26: SETORES | M26: CEPAC CONVERTIDO | P26: SETORES | Q26: CEPAC DESVINCULADO
F27: Estoque GERAL (aprovado pela 18.175/24) | G27: 2500000 | I27: LEILOADO | J27: 664030 | M27: ACA | N27: USO E PARÂMETROS | Q27: ACA | R27: USO E PARÂMETROS | X27: SALDO DE ESTOQUE MÁXIMO DISPONIVEL POR SETOR (Lei 13.769/04 + lei 18.175/24) | Z27: ESTOQUE (m²) PREVISTO PARA OS SETORES PELA LEI 18.175/24 DESCONTADAS PROPOSTAS APROVADAS | AB27: SALDO DE ESTOQUE GERAL DISPONIVEL PARA A OPERAÇÃO URBANA - lei 18.175/24 + ESTOQUE DEVOLVIDO POR DESVINCULAÇÃO E MUDANÇA DE USO
F28: Estoque consumido Lei 11.732/95 (*) | G28: 940000 | I28: COLOCAÇÃO PRIVADA | J28: 117452 | L28: HÉLIO PELEGRINO | M28: 266344 | N28: 33269 | P28: HÉLIO PELEGRINO | Q28: =348+424+1943+2211 -> 4926 | R28: 0 | X28: Residencial | Y28: Não Residencial | Z28: Residencial | AA28: Não Residencial | AB28: Residencial | AC28: Não Residencial
F29: LIMITE DE ESTOQUE - Lei 18.175/25 | G29: 1560000 | I29: CONVERTIDO | J29: -774382 | L29: FARIA LIMA | M29: 199360 | N29: 13377 | P29: FARIA LIMA | Q29: =1335+6009+2239+38 -> 9621 | R29: =45+1470+558 -> 2073 | X29: =N9 -> 0 | Y29: =O9 -> 0 | Z29: =P19 -> 68235.16 | AB29: =Z34+X35 -> 151598.03
F30: Estoque Consumido Lei 11.732/95 (**) | G30: 244719.95 | I30: EM CIRCULAÇÃO | J30: =SUM(J27:J29) -> 7100 | L30: PINHEIROS | M30: 93446 | N30: 14827 | P30: PINHEIROS | Q30: =2343+72 -> 2415 | R30: 2343 | X30: =N10 -> 7002.23 | Y30: =O10 -> 0 | Z30: =P20 -> 14046.33
F31: Estoque Consumido Lei 13.769/04 (***) | G31: =1065280.05+N10 -> 1072282.3 | I31: CEPAC - Total | J31: 1000000 | L31: OLIMPÍADAS | M31: 147927 | N31: 5832 | P31: OLIMPÍADAS | Q31: 174 | R31: 0 | X31: =N11 -> 0 | Y31: =O11 -> 0 | Z31: =P21 -> 31935.9
F32: Estoque Consumido Lei 18.175/24 | G32: =L24 -> 121398.4 | I32: CEPAC - Saldo | J32: =J31-(J27+J28) -> 218518 | L32: SUB-TOTAL | M32: =SUM(M28:M31) -> 707077 | N32: =SUM(N28:N31) -> 67305 | P32: TOTAL | Q32: =SUM(Q28:Q31) -> 17136 | R32: =SUM(R28:R31) -> 4416 | X32: =N12 -> 15994.2 | Y32: =O12 -> 0 | Z32: =P22 -> 14384.21
F33: Estoque Restituído após desvinculação e/ou alteração de Certidão (Portaria SMDU.G 074/2012 e Decreto 60435/2021) | G33: 0 | L33: TOTAL | M33: =M32+N32 -> 774382
F34: SALDO ESTOQUE GERAL DISPONÍVEL | G34: =G27-G28-G30-G31-G32 -> 121599.37 | P34: Obs: Verificar no site o detalhamento das desvinculações, com as respectivas datas de desvinculação, para observância do estabelecido no Decreto nº 53.094/2012, artigo 37, parágrafos § 4º e § 5º e Portaria nº 74/2012/SMDU.G | X34: =SUM(X29:X32) -> 22996.43 | Y34: =SUM(Y29:Y32) -> 0 | Z34: =SUM(Z29:AA32) -> 128601.6
F35: (*) Estoque consumido na lei 11.732/1998 | X35: =X34+Y34 -> 22996.43
F36: (**) Estoque consumido após a Lei 13.769/04 pago com outorga
F37: (***) Estoque consumido na lei 13.769/04

Sheet 5_18175
A1: STATUS PA | B1: ANALISE | E1: STATUS PA | F1: DEFERIDO
A2: SITUACAO | B2: (Tudo) | E2: SITUACAO | F2: VALIDA
A3: LEI | B3: 18.175/2024 | E3: LEI | F3: 18.175/2024
A4: REQUERIMENTO | B4: (Vários itens) | E4: REQUERIMENTO | F4: (Vários itens)
I5: BENEFICIOS
A6: Rótulos de Linha | B6: Soma de ACA-R | C6: Soma de ACA-NR | E6: Rótulos de Linha | F6: Soma de ACA-R | G6: Soma de ACA-NR | I6: R | K6: NR | Q6: Rótulos de Linha | R6: Soma de ACA-R | S6: Soma de ACA-NR
A7: HÉLIO PELEGRINO | B7: 4854.71 | C7: 175.83 | E7: HÉLIO PELEGRINO | F7: 23064.61 | G7: 13405.25 | I7: 239.24 | J7: 1758.8 | K7: 956.98 | Q7: HÉLIO PELEGRINO | R7: =23064.61-I7-J7 -> 21066.57 | S7: =13405.25-K7 -> 12448.27
A8: FARIA LIMA | E8: FARIA LIMA | F8: 19706.23 | G8: 8310.41 | I8: 475.08 | K8: 587.89 | Q8: FARIA LIMA | R8: =19706.23-I8 -> 19231.15 | S8: =8310.41-K8 -> 7722.52
A9: PINHEIROS | E9: PINHEIROS | F9: 26192.98 | G9: 0 | I9: 1407.54 | J9: 2871.34 | Q9: PINHEIROS | R9: =26192.98-I9-J9 -> 21914.1 | S9: 0
A10: OLIMPÍADAS | E10: OLIMPÍADAS | F10: 8415.63 | G10: 39872.16 | I10: 275.43 | K10: 1101.71 | L10: 1497.96 | M10: 4080 | N10: 1263.4 | O10: 1053.5 | Q10: OLIMPÍADAS | R10: =8415.63-I10 -> 8140.2 | S10: =39872.16-K10-L10-M10-N10-O10 -> 30875.59
A11: Total Geral | B11: 4854.71 | C11: 175.83 | E11: Total Geral | F11: 77379.45 | G11: 61587.82 | Q11: Total Geral | R11: =SUM(R7:R10) -> 70352.02 | S11: =SUM(S7:S10) -> 51046.38
K12: =K7+K8+K10+L10+M10+N10+O10 -> 10541.44
A13: STATUS PA | B13: ANALISE | E13: STATUS PA | F13: DEFERIDO
A14: SITUACAO | B14: (Tudo) | E14: SITUACAO | F14: VALIDA
A15: LEI | B15: 18.175/2024 | E15: LEI | F15: 18.175/2024
A16: REQUERIMENTO | B16: (Vários itens) | E16: REQUERIMENTO | F16: (Vários itens)
A18: Rótulos de Linha | B18: Soma de CEPAC ACA | C18: Soma de CEPAC PARAMETROS | E18: Rótulos de Linha | F18: Soma de CEPAC ACA | G18: Soma de CEPAC PARAMETROS
A19: HÉLIO PELEGRINO | B19: 1906 | C19: 0 | E19: HÉLIO PELEGRINO | F19: 25911 | G19: 0
A20: FARIA LIMA | E20: FARIA LIMA | F20: 17288 | G20: 0
A21: PINHEIROS | E21: PINHEIROS | F21: 9919 | G21: 0
A22: OLIMPÍADAS | E22: OLIMPÍADAS | F22: 33050 | G22: 3190
A23: Total Geral | B23: 1906 | C23: 0 | E23: Total Geral | F23: 86168 | G23: 3190
A25: STATUS PA | B25: (Tudo)
A26: SITUACAO | B26: (Tudo)
A27: LEI | B27: (Tudo)
A28: REQUERIMENTO | B28: DESVINCULACAO
A30: Rótulos de Linha | B30: Soma de ACA-R | C30: Soma de ACA-NR
A31: FARIA LIMA | B31: 7002.23
A32: PINHEIROS
A33: OLIMPÍADAS | B33: 15994.2
A34: (vazio)
A35: Total Geral | B35: 22996.43

Sheet 1_controle_codigo
A1: PROPOSTA | B1: CERTIDAO | C1: STATUS CERTIDAO | D1: ANO CERTIDAO | E1: INTERESSADO | F1: CONTRIBUINTE - SQL | G1: SETOR | H1: PA | I1: STATUS DO PA | J1: TIPO DE CONTRAPARTIDA
A2: XX-0000 | B2: XX-000/0000 | C2: VALIDA OU CANCELADA | D2: 0000 | E2: XXXXXXXXXX | F2: 000.000.0000-0 | G2: XXXXX | H2: 0000.0000/0000000-0 | I2: DEFERIDO, INDEFERIDO OU ANALISE | J2: OODC, CEPAC | K2: MODELO
A3: FL-0001 | B3: FL-005/1995 | D3: 1995 | E3: CAPEL | F3: 083.206.0054-5/ 0055-3/ 0056-1 | G3: FARIA LIMA | H3: 13-000.321-95*05 | I3: DEFERIDO
A4: FL-0002 | B4: FL-012/1995 | D4: 1995 | E4: COMEPAR MALIK | F4: 299.009.0040-3/ 0042-1/ 0043-8/ 0044-6/ 0045-4/ 0052-7/ 0054-3 | G4: FARIA LIMA | H4: 13-000.366-95*35 | I4: DEFERIDO
A5: FL-0003 | B5: FL-025/1996 | D5: 1996 | E5: SAO LOURENCO | F5: 015.080.0222-3/0045-1 | G5: FARIA LIMA | H5: 13-000.578-95*03 | I5: DEFERIDO
A6: FL-0004 | B6: FL-103/1996 | D6: 1996 | E6: JHS | F6: 016.154.0005-2/ 0021-4/ 0022-2/ 0034-6/ 0035-4 | H6: 13-000.586-95*31 | I6: DEFERIDO
A7: FL-0004 | B7: FL-135/1997 | D7: 1997 | E7: SERPLAN | F7: 016.154.0005-2, 016.154.0021-4, 016.154.0035-4, 016.154.0034-6, 016.154.0022-2, 016.154.0024-9, 016.154.0025-7 | H7: 1995-0.017.225-9 | I7: DEFERIDO
A8: FL-0005
A9: FL-0006
A10: FL-0007 | B10: FL-063/1997 | D10: 1997 | E10: VENDOME | F10: 299.014.0097-8/0081-1 | G10: HELIO PELEGRINO | H10: 1995-0.017.263-1 | I10: DEFERIDO
A11: FL-0007 | B11: FL-016/2000 | D11: 2000 | E11: VENDOME | F11: 299.014.0097-8/0081-1 | G11: HELIO PELEGRINO | H11: 1995-0.017.263-1 | I11: DEFERIDO
A12: FL-0008 | B12: FL-112/1997 | D12: 1997 | E12: PETER MURANYI | F12: 015.073.0120-0 | G12: PINHEIROS | H12: 1995-0.017.213-5 | I12: DEFERIDO
A13: FL-0009
A14: FL-0010 | B14: FL-038/1996 | D14: 1996 | E14: SOCIEDADE CIVIL PALMARES | F14: 083.007.0024-2/23-4/39-0/43-9/42-0 | G14: PINHEIROS | H14: 13-000.777-95*30 | I14: DEFERIDO
A15: FL-0011 | B15: FL-102/1996 | D15: 1996 | E15: LUAN | F15: 299.003.0349-9 | H15: 13-000.788-95*56 | I15: DEFERIDO
A16: FL-0011 | B16: FL-071/1997 | D16: 1997 | E16: LUAN | F16: 299.033.0349-9 | H16: 1995-0.017.301-8 | I16: DEFERIDO
A17: FL-0012 | B17: FL-061/1996 | D17: 1996 | E17: KAUFFMANN | F17: 299.022.0152-9/0026-3/0036-0/0029-8/0180-4 /0165-0 | G17: FARIA LIMA | H17: 13-000.795-95*11 | I17: DEFERIDO
A18: FL-0012 | B18: FL-074/1996 | D18: 1996 | E18: KAUFFMANN | F18: 299.022.0152-9/0026-3/0036-0/0029-8/0180-4/0165-0 | G18: FARIA LIMA | H18: 13-000.795-95*11 | I18: DEFERIDO
A19: FL-0013
A20: FL-0014 | B20: FL-020/1996 | D20: 1996 | E20: KLAPART | F20: 083.103.0064 -6/0017-4 | G20: PINHEIROS | H20: 13-000.911-95*10 | I20: DEFERIDO
A21: FL-0015 | B21: FL-065/1996 | D21: 1996 | E21: RACIONAL | F21: 299.019.0035-0, 299019-0032-6, 299.019.0087-3, 299.019.0033-4, 299.019.0034-2 | G21: FARIA LIMA | H21: 13-000.930-95*65 | I21: DEFERIDO
A22: FL-0016 | B22: FL-071/1996 | D22: 1996 | E22: TAQUARI | F22: 015.031.0034-0, 015.031.0035-9, 015.031.0036-7, 015.031.0037-5 | G22: FARIA LIMA | H22: 13-000.878-95*47 | I22: DEFERIDO
A23: FL-0017 | B23: FL-039/1996 | D23: 1996 | E23: MARITIMA | F23: 299.028.0045-7 | H23: 13-000.969-95*09 | I23: DEFERIDO
A24: FL-0018
A25: FL-0019 | B25: FL-010/1996 | D25: 1996 | E25: ACHE | F25: 083.007.0035-8 | G25: PINHEIROS | H25: 13-000.928.95*13 | I25: DEFERIDO
A26: FL-0019 | B26: FL-058/1996 | D26: 1996 | E26: RUY OHTAKE | F26: 083.007.0035-8 | G26: PINHEIROS | H26: 13-000.928.95*13 | I26: DEFERIDO | K26: PERMITIDO GABARITO ACIMA DE 25m (CNLU)
A27: FL-0019 | B27: FL-014/1998 | D27: 1998 | E27: ACHE | F27: 083.007.0005-6, 083.007.0027-7, 083.007.0028-5, 083.007.0035-8 | G27: PINHEIROS | H27: 1995-0.017.346-8 | I27: DEFERIDO
A28: FL-0019 | B28: FL-001/2000 | D28: 2000 | E28: ACHE | F28: 083.007.0005-6, 083.007.0027-7, 083.007.0028-5, 083.007.0035-8 | G28: PINHEIROS | H28: 1995-0.017.346-8 | I28: DEFERIDO
A29: FL-0020 | B29: FL-021/1996 | D29: 1996 | E29: GUSTAVO HALBREICH | F29: 015.074.0049-7/0111-6/0091-8 | G29: PINHEIROS | H29: 13-000.004-96*25 | I29: DEFERIDO
A30: FL-0021 | B30: FL-029/1996 | D30: 1996 | E30: FANY TABACOW | F30: 015.092.0016-9 | G30: PINHEIROS | H30: 13-000.069-96*70 | I30: DEFERIDO
A31: FL-0022 | B31: FL-034/1996 | D31: 1996 | E31: INPAR | F31: 299.073.0019-3/0018-5/0022-3/0020-7 | G31: OLIMPIADAS | H31: 13-000.111-96*35 | I31: DEFERIDO
A32: FL-0023
A33: FL-0024
A34: FL-0025
A35: FL-0026 | B35: FL-040/1997 | D35: 1997 | E35: ANSELMO RODRIGUES | F35: 015.100.0079-8 | G35: FARIA LIMA | H35: 13-000.204-96*41 | I35: DEFERIDO
A36: FL-0027
A37: FL-0028 | B37: FL-043/1997 | D37: 1997 | E37: GASPAR E ASSOCIADOS | F37: 083.110.0021-2 | G37: FARIA LIMA | H37: 13-000.211-96*80 | I37: DEFERIDO
A38: FL-0029 | B38: FL-042/2000 | D38: 2000 | E38: DAVILAR | F38: 299.124.0001- 1/0002-8/0003-6/0004-4/0005-2/0006-0/0007-9 | G38: FARIA LIMA | H38: 1996-0.029.276-0 | I38: DEFERIDO
A39: FL-0030
A40: FL-0031 | B40: FL-024/1997 | D40: 1997 | E40: ZABO | F40: 041.287.0017-7/0018-5/0019-3 e 0020-7 | G40: HELIO PELEGRINO | H40: 13-000.353-96*74 | I40: DEFERIDO
...

Sheet 2_CONTROLE_ESTOQUE
A1: CODIGO | B1: LEI | C1: PA (16 digitos) | D1: PA (12 digitos) | E1: DATA AUTUACAO PA | F1: STATUS PA | G1: INTERESSADO | H1: CNPJ | I1: CPF | J1: ENDEREÇO | K1: SETOR OUC | L1: REQUERIMENTO | M1: CONTRIBUINTE - SQ | N1: CONTRIBUINTE - L | O1: ÁREA DO TERRENO | P1: USO DA ACA | Q1: ACA-R (REAL) | R1: ACA-R BENEFICIOS | S1: ACA-R | T1: ACA-NR (REAL) | U1: ACA-NR (BENEFÍCIOS) | V1: ACA-NR | W1: ACA-TOTAL | X1: TIPO DE CONTRAPARTIDA | Y1: VALOR R$ | Z1: CEPAC ACA | AA1: CEPAC PARAMETROS | AB1: TOTAL CEPAC | AC1: CERTIDAO | AD1: SITUACAO | AE1: DATA CERTIDAO | AF1: NUVEM m² - R | AG1: NUVEM m² -nR | AH1: NUVEM m² | AI1: NUVEM CEPAC | AJ1: OBS | AK1: RESP/DATA
A2: FL-0095 | B2: 13.769/2004 | D2: 2013-0325611-4 | E2: 41579 | F2: DEFERIDO | G2: SAO JOSE DESENVOLVIMENTO IMOBILIARIO 33 LTDA. | H2: 10174781/0001-94; | J2: RUA FREDERIC CHOPIN, 20; | K2: FARIA LIMA | L2: VINCULACAO | M2: 083207; | N2: 0135-1; | O2: 287.82 | P2: R | Q2: 863.46 | W2: =T2+Q2 -> 863.46 | X2: CEPAC (título) | Z2: 785 | AB2: =AA2+Z2 -> 785 | AC2: FL-001/2014 | AD2: VALIDA | AE2: 41645 | AJ2: CERTIDÃO 04/12/SMDU/CTLU | AK2: AMANDA/08/07/2025
A3: FL-0148 | B3: 13.769/2004 | D3: 2005-0320407-9 | E3: 38702 | F3: DEFERIDO | G3: CONCEITO CONSTRUTORA E PARTICIPACOES LTDA. | H3: 71657464/0001-13; | J3: AVENIDA BRIGADEIRO FARIA LIMA; RUA TABAPUA; RUA JOSE GONCALVES OLIVEIRA | K3: HÉLIO PELEGRINO | L3: VINCULACAO | M3: 229008; | N3: 0075-1; 0027-1; 0024-7; 0025-8; 0023-9; 0026-9; 0022-0; 0021-2; 0019-0; 0043-3; 0076-1; 0077--8; 0014-6; | O3: 2878.34 | P3: NR | T3: 780.87 | W3: =T3+Q3 -> 780.87 | X3: CEPAC (título) | Z3: 975 | AA3: 173 | AB3: =AA3+Z3 -> 1148 | AC3: FL-004/2006 | AD3: VALIDA | AE3: 39016 | AJ3: CERTIDÃO COMPLEMENTAR (DE QUAL?) | AK3: AMANDA/08/07/2025
A4: FL-0211 | B4: 13.769/2004 | D4: 2003-0295416-0 | E4: 37937 | F4: DEFERIDO | G4: VR EMPREENDIMENTOS PARTICIPACOES E SERVICOS; SAINT PATRICK INCORPORADORA E PARTICIPACOES LTDA; SANTA CRUZ FOMENTO COMERCIAL LTDA.; CINCINATI HOLDINGS LTDA.; ESCALA EMPREENDIMENTOS E PARTICIPACOES LTDA.; VISBELA EMPREENDIMENTOS E PARTICIPACOES LTDA.; BANDO BMD LTDA.; | H4: 01150594/0001-80; 97355069/0001-70; 50117142/0001-01; 09092729/0001-00; 00338747/0001-54; 04036914/0001-63; 60892304/0001-32; | J4: AVENIDA BRIGADEIRO FARIA LIMA; | L4: VINCULACAO | M4: 015057; | N4: 0009-4; | O4: 9372 | W4: =T4+Q4 -> 0 | X4: CEPAC (título) | AA4: 2343 | AB4: =AA4+Z4 -> 2343 | AC4: FL-022/2010 | AD4: CANCELADA | AE4: 40456 | AK4: AMANDA/08/07/2025
A5: FL-0211 | B5: 13.769/2004 | D5: 2014-0161140-7 | E5: 41799 | F5: DEFERIDO | G5: VR EMPREENDIMENTOS PARTICIPACOES E SERVICOS; SAINT PATRICK INCORPORADORA E PARTICIPACOES LTDA; SANTA CRUZ FOMENTO COMERCIAL LTDA.; CINCINATI HOLDINGS LTDA.; ESCALA EMPREENDIMENTOS E PARTICIPACOES LTDA.; VISBELA EMPREENDIMENTOS E PARTICIPACOES LTDA.; BANDO BMD LTDA.; | H5: 01150594/0001-80; 97355069/0001-70; 50117142/0001-01; 09092729/0001-00; 00338747/0001-54; 04036914/0001-63; 60892304/0001-32; | J5: AVENIDA BRIGADEIRO FARIA LIMA; | L5: DESVINCULACAO | M5: 015057; | N5: 0009-4; | O5: 9372 | W5: =T5+Q5 -> 0 | X5: CEPAC (título) | AA5: 2343 | AB5: =AA5+Z5 -> 2343 | AC5: DV-001/2015 | AD5: VALIDA | AE5: 42095
A6: FL-0217 | B6: 13.769/2004 | D6: 2003-0324486-7 | E6: 37967 | F6: DEFERIDO | G6: BL EMPREENDIMENTOS SPE LTDA | H6: 07467969/0001-16; | J6: RUA DOUTOR RENATO PAES DE BARROS; RUA BENEDITO LAPIN; | K6: HÉLIO PELEGRINO | L6: VINCULACAO | M6: 016166; | N6: 0018-7; 0019-5; 0020-9; 0021-7; 0042-1; | O6: 1600 | P6: R | Q6: 4800 | W6: =T6+Q6 -> 4800 | X6: CEPAC (título) | Z6: 1920 | AB6: =AA6+Z6 -> 1920 | AC6: FL-001/2006 | AD6: VALIDA | AE6: 38764 | AK6: PRISCILA/12/05/2025
A7: FL-0218 | B7: 13.769/2004 | D7: 2003-0325166-9 | E7: 37970 | F7: DEFERIDO | G7: BOLSA DE IMÓVEIS DESENVOLVIMENTO IMOBILIÁRIO LTDA; TECNUM & CORPORATE EMPREENDIMENTOS IMOBILIÁRIOS LTDA; QUALITY BUILDING EMPREENDIMENTOS E PARTICIPAÇÕES LTDA | H7: 04913697/0001-42;64596046/0001-00;01490046/0001-07 | J7: RUA LEOPOLDO COUTO DE MAGALHÃES JUNIOR, 1.387 | K7: FARIA LIMA | L7: VINCULACAO | M7: 299019; | N7: 0084-9; 0085-7; 0080-6; 0051-2; 0004-0; 0062-8; | O7: 1646.88 | P7: R | Q7: 4940.97 | W7: =T7+Q7 -> 4940.97 | X7: CEPAC (título) | Z7: 3801 | AB7: =AA7+Z7 -> 3801 | AC7: FL-012/2007 | AD7: VALIDA | AE7: 39349 | AK7: LUCIANA/16/05/2025
A8: FL-0221 | B8: 13.769/2004 | C8: 7810.2020/0001473-9 | F8: DEFERIDO | G8: RAUL SABBAGA CHEDE | J8: RUA CANÁRIO; RUA INHAMBU; RUA CORONEL HUMAITÁ | K8: HÉLIO PELEGRINO | L8: VINCULACAO | M8: 041038; | N8: 0022-4; 0028-3; 0033-1; 0036-4; 0050-1; 0051-8; 0052-6 | O8: 6245.44 | P8: R | W8: =T8+Q8 -> 0 | X8: CEPAC (título) | Z8: 8070 | AB8: =AA8+Z8 -> 8070 | AD8: VALIDA | AE8: 38330 | AJ8: PROCESS INICIAL 2003-0.327.160-0 - CERTIDÃO 24//04/SEMPLA - EMITIDA POR SEMPLA - PAGTO PARTE CONTRAPARTIDA FINANCEIRA - PARTE CEPAC - | AK8: LUCIANA/16/05/2025
A9: FL-0230 | B9: 13.769/2004 | D9: 2004-0096854-8 | E9: 38093 | F9: DEFERIDO | G9: ATALANTA PARTICIPAÇÕES E PROPRIEDADES LTDA | H9: 04791780/0001-96; | J9: RUA IRACI, 707; ESQUINA COM A RUA HUNGRIA | K9: FARIA LIMA | L9: VINCULACAO | M9: 083231; | N9: 0049-7; 0050-0; 0051-9; 0052-7; 0053-5; 0054-3; 0055-1; 0056-1; 0057-8; 0058-6; 0059-4; 0060-8 | O9: 684.7 | P9: NR | T9: 2033 | W9: =T9+Q9 -> 2033 | X9: OODC (dinheiro) | Y9: 2365682 | AB9: =AA9+Z9 -> 0 | AD9: VALIDA | AE9: 38260 | AJ9: Pago R$ 2.365.682,00, conforme despacho da CTLU CERTIDÃO 17/04/SEMPLA | AK9: LUCIANA/16/05/2025
A10: FL-0235 | B10: 13.769/2004 | D10: 2004-0294005-5 | E10: 38336 | F10: DEFERIDO | G10: PALMARES EMPREENDIMENTOS E PARTICIPAÇÕES S/A | H10: 47218250/0001-66; | J10: AVENIDA BRIGADEIRO FARIA LIMA, 173; AVENIDA PEDROSO DE MORAES, 1.271 E 1.323 | K10: PINHEIROS | L10: VINCULACAO | M10: 083007; | N10: 0040-4; 0044-7; 0046-3; | O10: 2862.48 | P10: NR | W10: =T10+Q10 -> 0 | X10: CEPAC (título) | AA10: 254 | AB10: =AA10+Z10 -> 254 | AC10: FL-010/2009 | AD10: VALIDA | AE10: 39888 | AK10: LUCIANA/16/05/2025
A11: FL-0236 | B11: 13.769/2004 | D11: 2005-0022151-7 | E11: 38385 | F11: DEFERIDO | G11: DESTINY DE PARTICIPAÇÃO LTDA | H11: 05574820/0001-00; | J11: RUA CORONEL ARTHUR DE PAULA FERREIRA, 185, 191, 195, 203, 209, 215, 227, 237; RUA MONTE APRAZÍVEL, 410, 416 | K11: HÉLIO PELEGRINO | L11: VINCULACAO | M11: 041282; | N11: 0030-1; 00031-1; 0004-2; 0101-4; | O11: 1767 | P11: R | Q11: 1185 | W11: =T11+Q11 -> 1185 | X11: CEPAC (título) | Z11: 790 | AB11: =AA11+Z11 -> 790 | AC11: FL-008/2009 | AD11: VALIDA | AE11: 39874 | AK11: LUCIANA/16/05/2025
A12: FL-0237 | B12: 13.769/2004 | D12: 2004-0299325-6 | E12: 38344 | F12: DEFERIDO | G12: FADLO HAIDAR EMPREENDIMENTO IMOBILIÁRIO SPE LTDA | H12: 08541185/0001-53; | J12: RUA FADLO AIDAR | K12: HÉLIO PELEGRINO | L12: VINCULACAO | M12: 299077; | N12: 0264-1; | O12: 2443.3 | P12: R | Q12: 4886.6 | W12: =T12+Q12 -> 4886.6 | X12: CEPAC (título) | Z12: 1955 | AB12: =AA12+Z12 -> 1955 | AC12: FL-017/2008 | AD12: VALIDA | AE12: 39764 | AK12: LUCIANA/16/05/2025
A13: FL-0238 | B13: 13.769/2004 | D13: 2004-0158467-0 | E13: 38163 | F13: DEFERIDO | G13: NAÇÕES UNIDAS EMPREENDIMENTO IMOBILIÁRIO LTDA | H13: 05095230/0001-03; | J13: rua gomes de carvalho, 1996 | K13: FARIA LIMA | L13: VINCULACAO | M13: 299038; | N13: 0008-6; 0009-4; 0020-5; 0040-1; | O13: 5796.4 | P13: NR | T13: 17389.2 | W13: =T13+Q13 -> 17389.2 | X13: CEPAC (título) | Z13: 19322 | AA13: 773 | AB13: =AA13+Z13 -> 20095 | AC13: FL-002/2008 | AD13: VALIDA | AE13: 39525 | AK13: LUCIANA/16/05/2025
A14: FL-0242 | B14: 13.769/2004 | D14: 2007-0186164-5 | E14: 39245 | F14: DEFERIDO | G14: WTORRE CJ EMPREENDIMENTO IMOBILIARIO S/A. | H14: 59535849/0001-02; | J14: AVENIDA NAÇÕES UNIDAS ESQUINA COM RUA EUGENIO DE MEDEIROS | K14: PINHEIROS | L14: VINCULACAO | M14: 083103; | N14: 0064-6; | O14: 8457.39 | P14: NR | T14: 14386.38 | W14: =T14+Q14 -> 14386.38 | X14: CEPAC (título) | Z14: 8463 | AB14: =AA14+Z14 -> 8463 | AC14: FL-017/2007 | AD14: VALIDA | AE14: 39433 | AK14: AMANDA/13/05/2025
A15: FL-0245 | B15: 13.769/2004 | D15: 2007-0337168-8 | E15: 39384 | F15: DEFERIDO | G15: CICLAME INCORPORADORA LTDA; ASTROEMERIA INCORPORADORA LTDA; | H15: 07697863/0001-09; 07698130/0001-99 | J15: RUA CLAUDIO SOARES E RUA VALERIO DE CARVALHO | K15: PINHEIROS | L15: VINCULACAO | M15: 015073; | N15: 0120-0; 0067-0; 0078-6; 0084-0; 0085-9; | O15: 5266.57 | P15: NR | W15: =T15+Q15 -> 0 | X15: CEPAC (título) | AA15: 453 | AB15: =AA15+Z15 -> 453 | AC15: FL-002/2010 | AD15: VALIDA | AE15: 40185 | AJ15: COMPLEMENTA CERTIDÕES 112/97/SEMPLA - ACA DE 13.493,442 - Certidão 05/10/CTLU (Consumo de ACA) | AK15: AMANDA/13/05/2025
A16: FL-0247 | B16: 13.769/2004 | D16: 2008-0090243-9 | E16: 39531 | F16: DEFERIDO | G16: JORGE THOMAZ WEIL; PEDRO SYLVIO WEIL | I16: 678506778-20; 039696658-68; | J16: RUA DIOGO MOREIRA, 75 E 87 | K16: PINHEIROS | L16: VINCULACAO | M16: 015092; | N16: 0034-7; 0009-6; | O16: 621.11 | P16: NR | T16: 1863.33 | W16: =T16+Q16 -> 1863.33 | X16: CEPAC (título) | Z16: 1036 | AB16: =AA16+Z16 -> 1036 | AC16: FL-006/2009 | AD16: VALIDA | AE16: 39871 | AK16: AMANDA/13/05/2025
A17: FL-0248 | B17: 13.769/2004 | D17: 2005-0014951-4 | E17: 38376 | F17: DEFERIDO | G17: FVM DESENVOLVIMENTO IMOBILIARIO LTDA. | H17: 08169300/0001-00; | J17: RUA ALVORADA | K17: HÉLIO PELEGRINO | L17: VINCULACAO | M17: 299177; | N17: 0072-9; 0070-2; 0036-2; | O17: 800 | P17: R | Q17: 2400 | W17: =T17+Q17 -> 2400 | X17: CEPAC (título) | Z17: 960 | AA17: 70 | AB17: =AA17+Z17 -> 1030 | AC17: FL-014/2009 | AD17: VALIDA | AE17: 40008 | AJ17: QUANTIDADE DE CEPAC PARA ACA E PARÂMETROS EXTRAÍDO DA PLANILHA PUBLICADA | AK17: AMANDA/13/05/2025
A18: FL-0253 | B18: 13.769/2004 | C18: 7810.2022/0001829-0 | F18: DEFERIDO | G18: 2509 FUNDO DE INVESTIMENTO IMOBILIÁRIO – FII; ADMINISTRADORA PMV LTDA; | H18: 19419994/0001-03; 05083840/0001-89; | J18: RUA FUNCHAL 160; AVENIDA CHEDID JAFET 75; AVENIDA PRESIDENTE JUSCELINO KUBITSCHECK 1909; RUA PEQUETIBA, 170; | K18: OLIMPÍADAS | L18: VINCULACAO | M18: 299027; | N18: 0006-1; | O18: 38803.44 | P18: R | Q18: 1074.86 | W18: =T18+Q18 -> 1074.86 | X18: CEPAC (título) | Z18: 0 | AA18: 0 | AB18: =AA18+Z18 -> 0 | AC18: FL-001/2024 | AD18: VALIDA | AE18: 45517 | AK18: PRISCILA/11/09/2025
A19: FL-0302 | B19: 13.769/2004 | D19: 2005-0020668-2 | E19: 38384 | F19: DEFERIDO | G19: EVEN CONSTRUTORA E INCORPORADORA LTDA; PINHEIROS DESENVOLVIMENTO IMOBILIARIO LTDA; | H19: 43470988/0001-65; 07241467/0001-72; | J19: RUA FREDERICO HERMANN JUNIOR; RUA NICOLAU GAGLIARDI | K19: PINHEIROS | L19: VINCULACAO | M19: 083233; | N19: 0004-2; | O19: 7589.9 | P19: R | Q19: 22769.7 | W19: =T19+Q19 -> 22769.7 | X19: CEPAC (título) | Z19: 8133 | AB19: =AA19+Z19 -> 8133 | AC19: FL-002/2006 | AD19: VALIDA | AE19: 38786 | AK19: AMANDA/13/05/2025
A20: FL-0303 | B20: 13.769/2004 | D20: 2005-0020911-8 | E20: 38354 | F20: DEFERIDO | G20: CIPESA ENGENHARIA S/A | H20: 12272753/0001-32; | J20: RUA BENEDITO LAPIN; RUA BANDEIRA PAULISTA; | K20: HÉLIO PELEGRINO | L20: VINCULACAO | M20: 016167; | N20: 0091-2; 0090-4; 0089-0; 0088-2; 0087-4; 0131-5; 0132-3; | O20: 1404.76 | P20: R | Q20: 4212.33 | W20: =T20+Q20 -> 4212.33 | X20: CEPAC (título) | Z20: 1685 | AB20: =AA20+Z20 -> 1685 | AC20: FL-006/2006 | AD20: VALIDA | AE20: 39050 | AK20: GIULIA/13/05/2025
A21: FL-0304 | B21: 13.769/2004 | D21: 2005-0021493-6 | E21: 38385 | F21: DEFERIDO | G21: QUEIROZ GALVAO CYRELA EMPREENDIMENTOS E PARTICIPACOES S/A | H21: 06878430/0001-97; | J21: RUA HORACIO LAFER, 120; | K21: HÉLIO PELEGRINO | L21: VINCULACAO | M21: 299014; | N21: 0014-5;0016-1;0019-6; 0099-6; 0100-1; | O21: 2375 | P21: R | Q21: 7125 | W21: =T21+Q21 -> 7125 | X21: CEPAC (título) | Z21: 2850 | AB21: =AA21+Z21 -> 2850 | AC21: FL-003/2006 | AD21: VALIDA | AE21: 38897 | AK21: GIULIA/13/05/2025
A22: FL-0305 | B22: 13.769/2004 | D22: 2005-0256976-6 | E22: 38643 | F22: DEFERIDO | G22: F. REIS ADMINISTRACAO DE IMOVEIS LTDA | H22: 00076468/0001-60; | J22: RUA DAS OLIMPIADAS, 242; | K22: OLIMPÍADAS | L22: VINCULACAO | M22: 299050; | N22: 0085-0; | O22: 1040 | P22: NR | T22: 2079.1 | W22: =T22+Q22 -> 2079.1 | X22: CEPAC (título) | Z22: 2311 | AB22: =AA22+Z22 -> 2311 | AC22: FL-005/2006 | AD22: VALIDA | AE22: 39016 | AK22: GIULIA/13/05/2025
A23: FL-0306 | B23: 13.769/2004 | D23: 2005-0324078-4 | E23: 38707 | F23: DEFERIDO | G23: BOLSA DE IMOVEIS DESENVOLVIMENTO IMOBILIARIO LTDA | H23: 04913697/0001-42; | J23: RUA LEOPOLDO COUTO DE MAGALHAES JUNIOR, 1.151; | K23: FARIA LIMA | L23: VINCULACAO | M23: 299020; | N23: 0026-4; 0140-6; 0150-3; | O23: 1500 | P23: R | Q23: 4500 | W23: =T23+Q23 -> 4500 | X23: CEPAC (título) | Z23: 3462 | AB23: =AA23+Z23 -> 3462 | AC23: FL-008/2007 | AD23: VALIDA | AE23: 39254 | AK23: GIULIA/13/05/2025
A24: FL-0308 | B24: 13.769/2004 | D24: 2006-0079215-0 | E24: 38798 | F24: DEFERIDO | G24: BRALDECAR EMPREENDIMENTOS LTDA | H24: 55033252/0001-09; | J24: AVENIDA PRESIDENTE JUSCELINO KUBITSCHEK, 1327; | K24: OLIMPÍADAS | L24: ALTERACAO | M24: 299028; | N24: 0478-9; | O24: 4475 | P24: NR | T24: 13425 | W24: =T24+Q24 -> 13425 | X24: CEPAC (título) | Z24: 14917 | AB24: =AA24+Z24 -> 14917 | AC24: FL-014/2007 | AD24: VALIDA | AE24: 39399 | AJ24: CANCELA A CERTIDÃO FL-010/2007 | AK24: GIULIA/13/05/2025
A25: FL-0308 | B25: 13.769/2004 | D25: 2006-0079215-0 | E25: 38798 | F25: DEFERIDO | G25: BRALDECAR EMPREENDIMENTOS LTDA | H25: 55033252/0001-09; | J25: AVENIDA PRESIDENTE JUSCELINO KUBITSCHEK, 1327; | K25: OLIMPÍADAS | L25: VINCULACAO | M25: 299028; | N25: 0478-9; | O25: 4475 | P25: NR | T25: 13425 | W25: =T25+Q25 -> 13425 | X25: CEPAC (título) | Z25: 11127 | AB25: =AA25+Z25 -> 11127 | AC25: FL-010/2007 | AD25: CANCELADA | AE25: 39310 | AJ25: CANCELADA PELA CERTIDÃO FL014/2007 | AK25: GIULIA/13/05/2025
A26: FL-0314 | B26: 13.769/2004 | D26: 2007-0139265-3 | E26: 39198 | F26: DEFERIDO | G26: KALAPALO EMPREENDIMENTOS IMOBILIÁRIOS LTDA; GLIESE INCOPORADORA LTDA | H26: 07936960/0001-07; 08352433/0001-13; | J26: RUA INHAMBU; AVEMIDA JURITI; AVENIDA HÉLIO PELEGRINO; RUA TUIM; | K26: HÉLIO PELEGRINO | L26: VINCULACAO | M26: 041063; | N26: 0004-4; 0005-2; 0003-6; 0002-8; 0023-0; | O26: 6865 | P26: R | Q26: 20584.62 | W26: =T26+Q26 -> 20584.62 | X26: CEPAC (título) | Z26: 13530 | AB26: =AA26+Z26 -> 13530 | AC26: FL-008/2010 | AD26: VALIDA | AE26: 40261 | AK26: VITOR/15/05/2025
A27: FL-0314 | B27: 13.769/2004 | D27: 2007-0139265-3 | E27: 39198 | F27: DEFERIDO | G27: KALAPALO EMPREENDIMENTOS IMOBILIÁRIOS LTDA; GLIESE INCOPORADORA LTDA | H27: 07936960/0001-07; 08352433/0001-13; | J27: RUA INHAMBU; AVEMIDA JURITI; AVENIDA HÉLIO PELEGRINO; RUA TUIM; | K27: HÉLIO PELEGRINO | L27: VINCULACAO | M27: 041063; | N27: 0004-4; 0005-2; 0003-6; 0002-8; 0023-0; | O27: 6865 | P27: R | W27: =T27+Q27 -> 0 | X27: CEPAC (título) | AA27: 4554 | AB27: =AA27+Z27 -> 4554 | AC27: FL-008/2008 | AD27: VALIDA | AE27: 39609 | AK27: VITOR/15/05/2025
A28: FL-0315 | B28: 13.769/2004 | D28: 2007-0179306-2 | E28: 39237 | F28: DEFERIDO | G28: CAPH INCORPORADORA LTDA | H28: 08701394/0001-17; | J28: AVENIDA DOUTOR CARDOSO DE MELO Nº 585 | K28: HÉLIO PELEGRINO | L28: VINCULACAO | M28: 299104; | N28: 0027-6; 0025-1; 0024-1; 0065-9; 0066-7; 0067-5; 0116-7; 0113-2; 0051-9; 0052-7; 0070-5; 0115-9; | O28: 5800 | P28: R | Q28: 15501.12 | W28: =T28+Q28 -> 15501.12 | X28: CEPAC (título) | Z28: 5737 | AB28: =AA28+Z28 -> 5737 | AC28: FL-011/2008 | AD28: VALIDA | AE28: 39696 | AK28: VITOR/15/05/2025
A29: FL-0316 | B29: 13.769/2004 | D29: 2007-0235144-6 | E29: 39288 | F29: DEFERIDO | G29: CETUS EVEN EMPREENDIMENTOS IMOBILIÁRIOS LTDA | H29: 08747241/0001-00; | J29: RUA ARAGUARI Nº 472 | K29: HÉLIO PELEGRINO | L29: VINCULACAO | M29: 041078; | N29: 0087-3; 0026-1; 0025-3; 0054-7; | O29: 1641.4 | P29: R | Q29: 4915.4 | W29: =T29+Q29 -> 4915.4 | X29: CEPAC (título) | Z29: 4372 | AB29: =AA29+Z29 -> 4372 | AC29: FL-016/2007 | AD29: VALIDA | AE29: 39423 | AK29: VITOR/15/05/2025
A30: FL-0317 | B30: 13.769/2004 | D30: 2008-0078866-0 | E30: 39519 | F30: DEFERIDO | G30: F. REIS ADMINISTRAÇÃO DE IMÓVEIS LTDA | H30: 00076468/0001-60; | J30: AVENIDA DOUTOR CARDOSO DE MELO Nº 1038 | K30: OLIMPÍADAS | L30: VINCULACAO | M30: 299080; | N30: 0079-7; 0004-5; | O30: 1000 | P30: NR | T30: 2000 | W30: =T30+Q30 -> 2000 | X30: CEPAC (título) | Z30: 2167 | AB30: =AA30+Z30 -> 2167 | AC30: FL-009/2008 | AD30: VALIDA | AE30: 39624 | AK30: VITOR/15/05/2025
A31: FL-0318 | B31: 13.769/2004 | C31: 7810.2022/0000813-9 | E31: 43714 | F31: DEFERIDO | G31: FLPP FARIA LIMA PRIME PROPERTIES S/A | H31: 07349852/0001-38; | J31: AV. BRIGADEIRO FARIA LIMA, 3732 | K31: FARIA LIMA | L31: VINCULACAO | M31: 299020; | N31: 0269-0; | O31: 13458.64 | P31: NR | T31: 33109.95 | W31: =T31+Q31 -> 33109.95 | X31: CEPAC (título) | Z31: 47291 | AA31: 2775 | AB31: =AA31+Z31 -> 50066 | AC31: FL-007/2022 | AD31: VALIDA | AE31: 44772 | AK31: GIULIA/29/05/2025
A32: FL-0318 | B32: 13.769/2004 | C32: 7810.2019/0000820-6 | E32: 43714 | F32: DEFERIDO | G32: FLPP FARIA LIMA PRIME PROPERTIES S/A | H32: 07349852/0001-38; | J32: AV. BRIGADEIRO FARIA LIMA, RUA LEOPOLDO COUTO DE MAGALHÃES, RUA LÍCIO NOGUEIRA E RUA FERNANDES DE ABREU | K32: FARIA LIMA | L32: VINCULACAO | M32: 299020; | N32: 0037-1; 0039-6; 0053-1; 0045-0; 0060-4; 0040-1; 0038-8; 0236-4; 0170-8; 0141-4; 0164-3; 0166-1; 0036-1; 0268-2; | O32: 13034.02 | P32: NR | T32: 33109.96 | W32: =T32+Q32 -> 33109.96 | X32: CEPAC (título) | Z32: 47291 | AA32: 2775 | AB32: =AA32+Z32 -> 50066 | AC32: FL-006/2021 | AD32: CANCELADA | AE32: 44476 | AK32: GIULIA/29/05/2025
A33: FL-0318 | B33: 13.769/2004 | D33: 2007-0397221-5 | E33: 39444 | F33: DEFERIDO | G33: FLPP FARIA LIMA PRIME PROPERTIES S/A | H33: 07349852/0001-38; | J33: AV. BRIGADEIRO FARIA LIMA, RUA LEOPOLDO COUTO DE MAGALHÃES, RUA LÍCIO NOGUEIRA E RUA FERNANDES DE ABREU | K33: FARIA LIMA | L33: VINCULACAO | M33: 299020; | N33: 0037-1; 0039-6; 0053-1; 0045-0; 0060-4; 0040-1; 0038-8; 0236-4; 0170-8; 0141-4; 0164-3; 0166-1; 0036-1; 0268-2; | O33: 13034.02 | P33: NR | T33: 33109.96 | W33: =T33+Q33 -> 33109.96 | X33: CEPAC (título) | Z33: 47291 | AA33: 5014 | AB33: =AA33+Z33 -> 52305 | AC33: FL-008/2018 | AD33: CANCELADA | AE33: 43325 | AJ33: DUPLO CHECK SO VAI ATE ESTA CERTIDAO ( AS FL-006/2021 E FL-008/2018 NÃO APARECEM) | AK33: GIULIA/29/05/2025
A34: FL-0318 | B34: 13.769/2004 | D34: 2007-0397221-5 | E34: 39444 | F34: DEFERIDO | G34: FLPP FARIA LIMA PRIME PROPERTIES S/A | H34: 07349852/0001-38; | J34: AV. BRIGADEIRO FARIA LIMA, RUA LEOPOLDO COUTO DE MAGALHÃES, RUA LÍCIO NOGUEIRA E RUA FERNANDES DE ABREU | K34: FARIA LIMA | L34: VINCULACAO | M34: 299020; | N34: 0037-1; 0039-6; 0053-1; 0060-4; 0040-1; 0038-8; 0236-4; 0170-8; 0141-4; 0164-3; 0166-1; 0036-1; 0164-3; | O34: 12121.78 | P34: NR | T34: 33109.96 | W34: =T34+Q34 -> 33109.96 | X34: CEPAC (título) | Z34: 47899 | AA34: 2382 | AB34: =AA34+Z34 -> 50281 | AC34: FL-009/2014 | AD34: CANCELADA | AE34: 41894 | AK34: GIULIA/29/05/2025
A35: FL-0318 | B35: 13.769/2004 | D35: 2007-0397221-5 | E35: 39444 | F35: DEFERIDO | G35: FLPP FARIA LIMA PRIME PROPERTIES S/A, RANANA PARTICIPAÇÕES L TDA , EYRE EMPREENDIMENTOS E PARTICIPAÇÕES L TDA, CEFILI-CONSTRUÇÕES E ENGENHARIA L TDA; | H35: 07349852/0001-38; 04652521/0001-84; 05033236/0001-48; 61620654/0001-02; | J35: AV. BRIGADEIRO FARIA LIMA, RUA LEOPOLDO COUTO DE MAGALHÃES, RUA LÍCIO NOGUEIRA E RUA FERNANDES DE ABREU | K35: FARIA LIMA | L35: VINCULACAO | M35: 299020; | N35: 0037-1; 0053-1; 0060-4; 0040-1; 0038-8; 0170-8; 0141-4; 0164-3; 0078-7; 0163-5; 0082-5; 0081-0; 0080-9; 0079-5; 0132-5; 0039-6; 0045-0; 0052-3; 0168-6; 0136-8; 0135-1; 0134-1; 0003-5; 0153-8; 0006-1; 0008-6; 0092-2; 0093-0; 0137-6; 0138-4; | O35: 11748.75 | P35: NR | T35: 33109.96 | W35: =T35+Q35 -> 33109.96 | X35: CEPAC (título) | Z35: 2737 | AB35: =AA35+Z35 -> 2737 | AC35: FL-014/2010 | AD35: CANCELADA | AE35: 40319 | AJ35: Complementa a certidão FL-004/2009 | AK35: GIULIA/29/05/2025
A36: FL-0318 | B36: 13.769/2004 | D36: 2007-0397221-5 | E36: 39444 | F36: DEFERIDO | G36: FLPP EMPREENDIMENTOS IMOBILIÁRIOS S/A | H36: 07349852/0001-38; | J36: AV. BRIGADEIRO FARIA LIMA, RUA LEOPOLDO COUTO DE MAGALHÃES, RUA LÍCIO NOGUEIRA E RUA FERNANDES DE ABREU | K36: FARIA LIMA | L36: VINCULACAO | M36: 299020; | N36: 0037-1; 0053-1; 0060-4; 0040-1; 0038-8; 0078-7; 0163-5; 0082-5; 0081-0; 0080-9; 0079-5; 0132-5; 0039-6; 0045-0; 0052-3; 0168-6; 0136-8; 0135-1; 0134-1; 0003-5; 0153-8; 0006-1; 0008-6; 0092-2; 0093-0; 0137-6; 0138-4; | O36: 9352.25 | P36: NR | T36: 28056.75 | W36: =T36+Q36 -> 28056.75 | X36: CEPAC (título) | Z36: 45886 | AB36: =AA36+Z36 -> 45886 | AC36: FL-004/2009 | AD36: CANCELADA | AE36: 39862 | AK36: GIULIA/29/05/2025
A37: FL-0318 | B37: 13.769/2004 | D37: 2007-0397221-5 | E37: 39444 | F37: DEFERIDO | G37: FLPP SERVIÇOS DE COBRANÇA E DE INFORMAÇÕES CADASTRAIS | H37: 07349852/0001-38; | J37: AV. BRIGADEIRO FARIA LIMA, RUA LEOPOLDO COUTO DE MAGALHÃES, RUA LÍCIO NOGUEIRA E RUA FERNANDES DE ABREU | K37: FARIA LIMA | L37: VINCULACAO | M37: 299020; | N37: 0037-1; 0053-1; 0060-4; 0040-1; 0038-8; 0078-7; 0163-5; 0082-5; 0081-0; 0080-9; 0079-5; 0132-5; 0045-0; 0052-3; 0168-6; 0136-8; 0135-1; 0134-1; 0003-5; 0153-8; 0006-1; 0008-6; 0092-2; 0093-0; 0137-6; 0138-4; | O37: 9177.25 | P37: NR | T37: 27531.55 | W37: =T37+Q37 -> 27531.55 | X37: CEPAC (título) | Z37: 45886 | AB37: =AA37+Z37 -> 45886 | AC37: FL-001/2008 | AD37: CANCELADA | AE37: 39493 | AK37: GIULIA/29/05/2025
A38: FL-0319 | B38: 13.769/2004 | D38: 2010-0089023-2 | E38: 40267 | F38: DEFERIDO | G38: YUNY GTIS ATILIO INNOCENTI EMPREENDIMENTOS LTDA | H38: 09234157/0001-56; | J38: RUA PROFESSOR ATILIO INNOCENTI, 165 E 193, RUA LEOPOLDO COUTO MAGALHAES JUNIOR 797 E 807 E RUA BELCHIOR SOARES, 28, 40, 50, 56, 64, 68, 78, 187, 197, 225 E 237; | K38: HÉLIO PELEGRINO | L38: ALTERACAO | M38: 299021; | N38: 0135-4; 0133-8; 0061-7; 0060-9; 0062-5; 0064-1; 0066-8; 0067-6; 0068-4; 0069-2; 0071-4; 0072-2; 0070-6; 0065-1; 0063-3; | O38: 3669.12 | P38: NR | T38: 11007.36 | W38: =T38+Q38 -> 11007.36 | X38: CEPAC (título) | Z38: 9540 | AB38: =AA38+Z38 -> 9540 | AC38: FL-016/2010 | AD38: VALIDA | AE38: 40381 | AJ38: NO DUPLO CHECK, consta a diferença. Porém, a presente certidão cancelou sua anteiror, então crieo que nossa planilha revela o que realmente ocorreu. PARA AVALIAÇÃO GT - incluir no relatório CANCELA A CERTIDÃO FL-012/2009 | AK38: GIULIA/29/05/2025
A39: FL-0319 | B39: 13.769/2004 | D39: 2010-0089023-2 | E39: 40267 | F39: DEFERIDO | G39: YUNY GTIS ATILIO INNOCENTI EMPREENDIMENTOS E PARTICIPACOES LTDA | H39: 09234157/0001-56; | J39: RUA PROFESSOR ATILIO INNOCENTI, 165 E 193 E RUA BELCHIOR SOARES, 40, 50, 56, 64, 68, 78, 187, 197 E 225; | K39: HÉLIO PELEGRINO | L39: ALTERACAO | M39: 299021; | N39: 0135-4; 0133-8; 0064-1; 0066-8; 0067-6; 0068-4; 0069-2; 0071-4; 0072-2; 0070-6; 0065-1; | O39: 3096.86 | P39: NR | T39: 9290.58 | W39: =T39+Q39 -> 9290.58 | X39: CEPAC (título) | Z39: 8672 | AB39: =AA39+Z39 -> 8672 | AC39: FL-012/2009 | AD39: CANCELADA | AE39: 39955 | AJ39: CANCELA A CERTIDÃO FL-018/2008 | CANCELADA PELA CERTIDÃO FL-016/2010 | AK39: GIULIA/29/05/2025
A40: FL-0319 | B40: 13.769/2004 | D40: 2010-0089023-2 | E40: 40267 | F40: DEFERIDO | G40: YUNY GTIS ATILIO INNOCENTI EMPREENDIMENTOS E PARTICIPACOES LTDA | H40: 09234157/0001-56; | J40: RUA PROFESSOR ATILIO INNOCENTI | K40: HÉLIO PELEGRINO | L40: VINCULACAO | M40: 299021; | N40: 0135-4; 0133-8; | O40: 2198.69 | P40: NR | T40: 6596.07 | W40: =T40+Q40 -> 6596.07 | X40: CEPAC (título) | Z40: 6597 | AB40: =AA40+Z40 -> 6597 | AC40: FL-018/2008 | AD40: CANCELADA | AE40: 39770 | AJ40: CANCELADA PELA CERTIDÃO FL-012/2009 | AK40: GIULIA/29/05/2025
...

Sheet 3_controle_certidoes
A1: TIPO | B1: PROCESSO | C1: DATA DA EMISSAO | D1: PROPOSTA | E1: OUC | F1: NUMERO | G1: ANO_CERTIDAO | H1: NUMERO DA CERTIDAO
C2: XX/XX/XXXX | D2: XX-0000 | E2: XX | F2: 000 | G2: 0 | H2: XX-000/0000 | J2: MODELO
A3: ALTERAÇÃO | B3: 7810.2024/0001277-6 | C3: 45835 | D3: FL-0399 | E3: FL | F3: 001 | G3: 2025 | H3: FL-001/2025
A4: ALTERAÇÃO | B4: 7810.2024/0001318-7 | C4: 45835 | D4: FL-0414 | E4: FL | F4: 002 | G4: 2025 | H4: FL-002/2025
A5: ALTERAÇÃO | B5: 7810.2024/0001498-1 | C5: 45856 | D5: FL-9413 | E5: FL | F5: 003 | G5: 2025 | H5: FL-003/2025
A6: ALTERAÇÃO | B6: 7810.2024/0001324-1 | C6: 45511 | D6: FL-0383 | E6: FL | F6: 004 | G6: 2025 | H6: FL-004/2025
A7: DESVINCULAÇÃO | B7: 7810.2025/0000957-2 | D7: FL-0414 | E7: FL | F7: 001 | G7: 2025 | H7: DV-001/2025
A8: ALTERAÇÃO | B8: 7810.2025/0000957-2 | C8: 45954 | D8: FL-0414 | E8: FL | F8: 005 | G8: 2025 | H8: FL-005/2025
A9: ALTERAÇÃO | B9: 1010.2025/0008826-4 | C9: 45946 | D9: FL-0424 | E9: FL | F9: 006 | G9: 2025 | H9: FL-006/2025
A10: VINCULAÇÃO | B10: 1010.2025/0008932-5 | C10: 45951 | D10: FL-0457 | E10: FL | F10: 007 | G10: 2025 | H10: FL-007/2025
A11: VINCULAÇÃO | B11: 1010.2025/0008862-0 | C11: 45951 | D11: FL-0452 | E11: FL | F11: 008 | G11: 2025 | H11: FL-008/2025
A12: VINCULAÇÃO | B12: 1010.2025/0008856-6 | C12: 45958 | D12: FL-0451 | E12: FL | F12: 009 | G12: 2025 | H12: FL-009/2025
A13: VINCULAÇÃO | B13: 1010.2025/0008833-7 | C13: 45958 | D13: FL-0445 | E13: FL | F13: 010 | G13: 2025 | H13: FL-010/2025
A14: VINCULAÇÃO | B14: 1010.2025/0008838-8 | C14: 45958 | D14: FL-0447 | E14: FL | F14: 011 | G14: 2025 | H14: FL-011/2025
A15: ALTERAÇÃO | B15: 1010.2025/0008851-5 | C15: 45958 | D15: FL-0399 | E15: FL | F15: 012 | G15: 2025 | H15: FL-012/2025
A16: VINCULAÇÃO | B16: 1010.2025/0008831-0 | C16: 45960 | D16: FL-0444 | E16: FL | F16: 013 | G16: 2025 | H16: FL-013/2025
A17: VINCULAÇÃO | B17: 1010.2025/0008877-9 | C17: 45959 | D17: FL-0454 | E17: FL | F17: 014 | G17: 2025 | H17: FL-014/2025
A18: VINCULAÇÃO | B18: 1010.2025/0008829-9 | C18: 45959 | D18: FL-0442 | E18: FL | F18: 015 | G18: 2025 | H18: FL-015/2025
A19: VINCULAÇÃO | B19: 1010.2025/0008837-0 | C19: 45966 | D19: FL-0446 | E19: FL | F19: 016 | G19: 2025 | H19: FL-016/2025
... A29: VINCULAÇÃO | B29: 1010.2025/0008885-0 | C29: 46007 | D29: FL-0456 | E29: FL | F29: 025 | G29: 2025 | H29: FL-025/2025
A30: VINCULAÇÃO | B30: 1010.2025/0008830-2 | D30: FL-0443 | E30: FL | F30: 001 | G30: 2026 | H30: FL-001/2026
A31: DESVINCULAÇÃO | B31: 7810.2025/0001181-0 | D31: FL-0114 | E31: FL | F31: 001 | G31: 2026 | H31: DV-001/2026
A32: DESVINCULAÇÃO | B32: 7810.2025/0001104-6 | C32: 45963 | D32: FL-0383 | E32: DV | F32: 002 | G32: 2025 | H32: DV-002/2025
A33: VINCULAÇÃO | B33: 1010.2025/0008830-2 | C33: 46038 | D33: FL-0443 | E33: FL | F33: 001 | G33: 2026 | H33: FL-001/2026
E35: FL | F35: 002 | G35: 2026 | H35: FL-002/2026 | I35: próxima numeração (inserir linha acima) | J35: VINCULAÇÃO
E36: FL | F36: 002 | G36: 2026 | H36: DV-002/2026 | I36: próxima numeração (inserir linha acima) | J36: DESVINCULAÇÃO

Sheet 4_resumo_propostas
B1: CERTIDAO - 1 | C1: CERTIDAO - 2 | D1: CERTIDAO - 3 | E1: CERTIDAO - 4 | F1: CERTIDAO - 5 | G1: CERTIDAO - 6 | H1: CERTIDAO - 7 | I1: CERTIDAO - 8
A2: FL-0001 | B2: FL-005/1995
A3: FL-0002 | B3: FL-012/1995
A4: FL-0003 | B4: FL-025/1996
A5: FL-0004 | B5: FL-103/1996 | C5: FL-135/1997
A6: FL-0005 | B6: FL-044/1996
A7: FL-0006
A8: FL-0007 | B8: FL-063/1997 | C8: FL-016/2000
A9: FL-0008 | B9: FL-112/1997
A10: FL-0009
A11: FL-0010 | B11: FL-038/1996
A12: FL-0011 | B12: FL-102/1996 | C12: FL-071/1997
A13: FL-0012 | B13: FL-061/1996 | C13: FL-074/1996
A14: FL-0013
A15: FL-0014 | B15: FL-020/1996
A16: FL-0015 | B16: FL-065/1996
A17: FL-0016 | B17: FL-071/1996
A18: FL-0017 | B18: FL-039/1996
A19: FL-0018
A20: FL-0019 | B20: FL-010/1996 | C20: FL-058/1996 | D20: FL-014/1998 | E20: FL-001/2000
A21: FL-0020 | B21: FL-021/1996
A22: FL-0021 | B22: FL-029/1996
A23: FL-0022 | B23: FL-034/1996
A24: FL-0023
A25: FL-0024
A26: FL-0025
A27: FL-0026 | B27: FL-040/1997
A28: FL-0027
A29: FL-0028 | B29: FL-043/1997
A30: FL-0029 | B30: FL-042/2000
A31: FL-0030
A32: FL-0031 | B32: FL-024/1997 | C32: FL-002/2004
A33: FL-0032 | B33: FL-104/1996
A34: FL-0033 | B34: FL-033/1997
A35: FL-0034 | B35: FL-032/1997 | C35: FL-001/1998
A36: FL-0035 | B36: FL-041/1998
A37: FL-0036 | B37: FL-058/1997 | C37: FL-040/1998
A38: FL-0037
A39: FL-0038 | B39: FL-031/1997
A40: FL-0039 | B40: FL-078/1997 | C40: FL-032/1998
...

Sheet METADADOS
A2: Variáveis | B2: Descrição da Variável | C2: Exemplo:
A3: CODIGO | B3: Número da PROPOSTA de vinculação de CEPACs. Campo alfa numérico. Iniciar o número 9 quando houver remembramento de proposta. Iniciar com a letra X quando houver duplicidade de códigos de proposta (em casos de equivocos, para identificar que são propostas diferentes. Letra X incluída na Proposta mais recente). | C3: XX-0000 ou XX-9000 ou XX-X000
A4: LEI | B4: Lei válida na emissão da certidão | C4: 13.769/2004, 18.175/2024 | D4: FAZER LISTA SUSPENSA DAS LEIS
A5: PA | B5: Número do processo administrativo gerado quando do protocolo da solicitação inicial do interessado. | C5: 0000.0000/0000000-0 ou 0000-0.000.000-0 | D5: novo padrão
A6: DATA AUTUACAO PA | B6: Data de abertura, email do Interessado | C6: xx/xx/xxxx | D6: novo padrão
A7: STATUS PA | B7: Situação atual do processo administrativo | C7: DEFERIDO, INDEFERIDO, ANALISE | D7: FIXO
A8: INTERESSADO | B8: Nome do Interessado. Escrever sem acento. TUDO MAIUSCULO | C8: XXXXXXXXXXXXXXXXX
A9: CNPJ | B9: Número do CNPJ do interessado | C9: xx.xxx.xxx/xxxx-xx | D9: Novo padrão
A10: ENDEREÇO | B10: Colocar nome da rua e número se houver, escrever nome COMPLETO | C10: xxxxxxxxxxxxxxxxx, 000
A11: SETOR OUC | B11: XXX | C11: CHUCRI ZAIDAN, BERRINI, BROOKLIN, JABAQUARA, MARGINAL PINHEIROS | D11: FAZER LISTA SUSPENSA DO SETOR POR OUC
A12: REQUERIMENTO | B12: Tipo da solicitação realizada | C12: VINCULACAO, ALTERACAO, DESVINCULACAO | D12: FAZER LISTA SUSPENSA DO SETOR POR OUC
A13: CONTRIBUINTE - SQ | B13: setor e lote dos imóveis (seja um sejam vários) separador ";" | C13: XXXXXX; OU XXXXXX;XXXXXX; | D13: ALTERADO - RODGER
A14: CONTRIBUINTE - L | B14: lote dos imóveis (seja um sejam vários) separador ";" | C14: xxxx-x; xxxx-x; xxxx-x; xxxx-x
A15: ÁREA DO TERRENO | B15: Quantidade de m² que o terreno possui (seja um SQL, seja união de vários) utilizar sempre o menor número (real ou escritura) | C15: x.xxx,xx | D15: QUANDO EXISTIR MAIS DE 2 CASAS DEPOIS DA VÍRGULA, ATÉ O NÚMERO 5 ARREDONDAMENTO PARA BAIXO IGUAL OU MAIOR QUE 5 ARREDONDAMENTO PARA CIMA
A16: USO DA ACA | B16: Categoria de uso definida para ACA do empreendimento | C16: R, NR, MISTO | D16: FAZER LISTA SUSPENSA DO SETOR POR OUC
A17: ACA-R | B17: área de construção adicional de uso residencial | C17: x.xxx,xx
A18: ACA-NR | B18: área de construção adicional de uso não residencial | C18: x.xxx,xx
A19: ACA-TOTAL | B19: área de construção adicional total do empreendimento | C19: x.xxx,xx
A20: TIPO DE CONTRAPARTIDA | B20: Tipo de pagamento da outorga onerosa | C20: OODC (dinheiro) CEPAC (título) | D20: FAZER LISTA SUSPENSA DO SETOR POR OUC
A21: VALOR R$ | B21: Pagamento realizado em dinheiro | C21: xx.xxx.xxx,xx | D21: COLUNA SUPRIMIDA
A22: CEPAC ACA | B22: Quatidade de títulos vinculados para ACA | C22: X.XXX
A23: CEPAC PARAMETROS | B23: Quatidade de títulos vinculados para parâmetro urbanísticos | C23: X.XXX
A24: TOTAL CEPAC | B24: Quantidade total de CEPAC vinculada | C24: X.XXX
A25: CERTIDAO | B25: Código da certidão emitida | C25: AB-xxx/2024, AE-xxx/2024, FL-xxx/2024
A26: SITUACAO | B26: Situação da certidão | C26: VALIDA (quando for a ultima certidão emitida) CANCELADA (certidão anterior) | D26: FAZER LISTA SUSPENSA DO SETOR POR OUC
A27: DATA CERTIDAO | B27: Data de emissão da certidão | C27: xx/xx/xxxx
A28: NUVEM m² - R | B28: área de construção adicional de uso residencial na NUVEM | C28: x.xxx,xx
A29: NUVEM m² - nR | B29: área de construção adicional de uso não residencial na NUVEM | C29: x.xxx,xx
A30: NUVEM m² | B30: campo preenchido com de o quantidade de m² constante nas observações na certidão | C30: x.xxx,xx
A31: NUVEM CEPAC - R
A32: NUVEM CEPAC - nR
A33: NUVEM CEPAC | B33: campo preenchido com o quantidade de CEPAC constante nas observações na certidão | C33: XX
A34: OBS | B34: Campo livre para informações complementares. CANCELADA PELA CERTIDÃO XXX | C34: sem padrão
A35: RESP/DATA | B35: Nome de quem realizou o cadastro e data do cadastro | C35: nome/00/00/2024
B36: RETORNO ESTOQUE E CEPAC (DESVINCULAÇÃO) | C36: A DATA QUE VOLTA O CEPAC E O ESTOQUE É SEMPRE A DATA DE PUBLICAÇÃO DO DESPACHO DEFERIDO!

Sheet lista_suspensa
B2: STATUS PA | C2: SETORES | D2: STATUS CERTIDAO | E2: LEI | F2: REQUERIMENTO
B3: DEFERIDO | C3: PINHEIROS | D3: VALIDA | E3: 13.769/2004 | F3: VINCULACAO
B4: ANALISE | C4: FARIA LIMA | D4: CANCELADA | E4: 18.175/2024 | F4: DESVINCULACAO
B5: INDEFERIDO | C5: HÉLIO PELEGRINO | F5: ALTERACAO
C6: OLIMPÍADAS
